<?xml version="1.0" encoding="utf-8"?>
<!-- This URDF was automatically created by SolidWorks to URDF Exporter! Originally created by Stephen Brawner (brawner@gmail.com) 
     Commit Version: 1.6.0-4-g7f85cfe  Build Version: 1.6.7995.38578
     For more information, please see http://wiki.ros.org/sw_urdf_exporter -->
<robot
  name="amr_bot">
  <link
    name="base_footprint">
    <inertial>
      <origin
        xyz="0.37605 0.49174 0.51412"
        rpy="0 0 0" />
      <mass
        value="9.4248E-05" />
      <inertia
        ixx="7.0921E-09"
        ixy="1.0074E-56"
        ixz="-2.732E-42"
        iyy="7.0921E-09"
        iyz="2.549E-23"
        izz="4.7124E-11" />
    </inertial>
    <visual>
      <origin
        xyz="0 0 0"
        rpy="0 0 0" />
      <geometry>
        <mesh
          filename="package://amr_bot/meshes/base_footprint.STL" />
      </geometry>
      <material
        name="">
        <color
          rgba="0.79216 0.81961 0.93333 1" />
      </material>
    </visual>
    <collision>
      <origin
        xyz="0 0 0"
        rpy="0 0 0" />
      <geometry>
        <mesh
          filename="package://amr_bot/meshes/base_footprint.STL" />
      </geometry>
    </collision>
  </link>
  <link
    name="base_link">
    <inertial>
      <origin
        xyz="-0.050771 0.0017522 0.25697"
        rpy="0 0 0" />
      <mass
        value="150" />
      <inertia
        ixx="1.4246"
        ixy="-9.8747E-06"
        ixz="-0.032685"
        iyy="1.9347"
        iyz="2.6064E-06"
        izz="3.0189" />
    </inertial>
    <visual>
      <origin
        xyz="0 0 0"
        rpy="0 0 0" />
      <geometry>
        <mesh
          filename="package://amr_bot/meshes/base_link.STL" />
      </geometry>
      <material
        name="">
        <color
          rgba="0.79216 0.81961 0.93333 1" />
      </material>
    </visual>
    <collision>
      <origin
        xyz="0 0 0"
        rpy="0 0 0" />
      <geometry>
        <mesh
          filename="package://amr_bot/meshes/base_link.STL" />
      </geometry>
    </collision>
  </link>
  <joint
    name="base_joint"
    type="fixed">
    <origin
      xyz="0.40456 -0.53802 0.48728"
      rpy="1.5708 0 0" />
    <parent
      link="base_footprint" />
    <child
      link="base_link" />
    <axis
      xyz="0 0 0" />
  </joint>
  <link
    name="l_wheel_link">
    <inertial>
      <origin
        xyz="-1.5761E-08 -0.029667 -1.6217E-08"
        rpy="0 0 0" />
      <mass
        value="1.2164" />
      <inertia
        ixx="0.0044416"
        ixy="4.9269E-11"
        ixz="-4.3509E-07"
        iyy="0.0082257"
        iyz="7.37E-11"
        izz="0.0044446" />
    </inertial>
    <visual>
      <origin
        xyz="0 0 0"
        rpy="0 0 0" />
      <geometry>
        <mesh
          filename="package://amr_bot/meshes/l_wheel_link.STL" />
      </geometry>
      <material
        name="">
        <color
          rgba="0.79216 0.81961 0.93333 1" />
      </material>
    </visual>
    <collision>
      <origin
        xyz="0 0 0"
        rpy="0 0 0" />
      <geometry>
        <mesh
          filename="package://amr_bot/meshes/l_wheel_link.STL" />
      </geometry>
    </collision>
  </link>
  <joint
    name="l_wheel_joint"
    type="continuous">
    <origin
      xyz="-0.03061 0.34088 0.06"
      rpy="0 0 0" />
    <parent
      link="base_link" />
    <child
      link="l_wheel_link" />
    <axis
      xyz="0 -1 0" />
  </joint>
  <link
    name="r_wheel_link">
    <inertial>
      <origin
        xyz="-1.5453E-08 0.029667 1.6511E-08"
        rpy="0 0 0" />
      <mass
        value="1.2164" />
      <inertia
        ixx="0.0044416"
        ixy="-4.7872E-11"
        ixz="4.9256E-07"
        iyy="0.0082257"
        iyz="7.4615E-11"
        izz="0.0044446" />
    </inertial>
    <visual>
      <origin
        xyz="0 0 0"
        rpy="0 0 0" />
      <geometry>
        <mesh
          filename="package://amr_bot/meshes/r_wheel_link.STL" />
      </geometry>
      <material
        name="">
        <color
          rgba="0.79216 0.81961 0.93333 1" />
      </material>
    </visual>
    <collision>
      <origin
        xyz="0 0 0"
        rpy="0 0 0" />
      <geometry>
        <mesh
          filename="package://amr_bot/meshes/r_wheel_link.STL" />
      </geometry>
    </collision>
  </link>
  <joint
    name="r_wheel_joint"
    type="continuous">
    <origin
      xyz="-0.03061 -0.34086 0.06"
      rpy="0 0 0" />
    <parent
      link="base_link" />
    <child
      link="r_wheel_link" />
    <axis
      xyz="0 1 0" />
  </joint>
  <link
    name="laser_link">
    <inertial>
      <origin
        xyz="-7.8753E-05 4.4713E-05 -0.045208"
        rpy="0 0 0" />
      <mass
        value="0.5925" />
      <inertia
        ixx="0.00070857"
        ixy="-1.3149E-06"
        ixz="1.5954E-06"
        iyy="0.00070664"
        iyz="3.8009E-07"
        izz="0.00080931" />
    </inertial>
    <visual>
      <origin
        xyz="0 0 0"
        rpy="0 0 0" />
      <geometry>
        <mesh
          filename="package://amr_bot/meshes/laser_link.STL" />
      </geometry>
      <material
        name="">
        <color
          rgba="0.79216 0.81961 0.93333 1" />
      </material>
    </visual>
    <collision>
      <origin
        xyz="0 0 0"
        rpy="0 0 0" />
      <geometry>
        <mesh
          filename="package://amr_bot/meshes/laser_link.STL" />
      </geometry>
    </collision>
  </link>
  <joint
    name="laser_joint"
    type="fixed">
    <origin
      xyz="0.40693 -0.00011921 0.23489"
      rpy="0 0 0" />
    <parent
      link="base_link" />
    <child
      link="laser_link" />
    <axis
      xyz="0 0 0" />
  </joint>
  <link
    name="camera_link">
    <inertial>
      <origin
        xyz="-0.013293 -0.0014081 2.3419E-05"
        rpy="0 0 0" />
      <mass
        value="0.036474" />
      <inertia
        ixx="2.3405E-05"
        ixy="-2.1067E-07"
        ixz="-1.0144E-08"
        iyy="3.5064E-06"
        iyz="1.6649E-09"
        izz="2.3613E-05" />
    </inertial>
    <visual>
      <origin
        xyz="0 0 0"
        rpy="0 0 0" />
      <geometry>
        <mesh
          filename="package://amr_bot/meshes/camera_link.STL" />
      </geometry>
      <material
        name="">
        <color
          rgba="0.70196 0.70196 0.70196 1" />
      </material>
    </visual>
    <collision>
      <origin
        xyz="0 0 0"
        rpy="0 0 0" />
      <geometry>
        <mesh
          filename="package://amr_bot/meshes/camera_link.STL" />
      </geometry>
    </collision>
  </link>
  <joint
    name="camera_joint"
    type="fixed">
    <origin
      xyz="0.46939 -0.00028866 0.27549"
      rpy="0 0 0" />
    <parent
      link="base_link" />
    <child
      link="camera_link" />
    <axis
      xyz="0 0 0" />
  </joint>
  <link
    name="imu">
    <inertial>
      <origin
        xyz="-0.00011027 -0.00033758 -0.0047293"
        rpy="0 0 0" />
      <mass
        value="0.022761" />
      <inertia
        ixx="6.449E-06"
        ixy="2.5391E-09"
        ixz="2.4684E-09"
        iyy="6.4691E-06"
        iyz="-5.981E-10"
        izz="1.2787E-05" />
    </inertial>
    <visual>
      <origin
        xyz="0 0 0"
        rpy="0 0 0" />
      <geometry>
        <mesh
          filename="package://amr_bot/meshes/imu.STL" />
      </geometry>
      <material
        name="">
        <color
          rgba="0.79216 0.81961 0.93333 1" />
      </material>
    </visual>
    <collision>
      <origin
        xyz="0 0 0"
        rpy="0 0 0" />
      <geometry>
        <mesh
          filename="package://amr_bot/meshes/imu.STL" />
      </geometry>
    </collision>
  </link>
  <joint
    name="imu_joint"
    type="fixed">
    <origin
      xyz="-0.020559 -0.0073322 0.016032"
      rpy="0 0 0" />
    <parent
      link="base_link" />
    <child
      link="imu" />
    <axis
      xyz="0 0 0" />
  </joint>
  <link
    name="sickcam_link">
    <inertial>
      <origin
        xyz="0.033916 -0.00010743 2.0961E-13"
        rpy="0 0 0" />
      <mass
        value="0.38171" />
      <inertia
        ixx="0.0003602"
        ixy="-1.7782E-07"
        ixz="-1.1037E-14"
        iyy="0.00030406"
        iyz="-4.2545E-12"
        izz="0.00035182" />
    </inertial>
    <visual>
      <origin
        xyz="0 0 0"
        rpy="0 0 0" />
      <geometry>
        <mesh
          filename="package://amr_bot/meshes/sickcam_link.STL" />
      </geometry>
      <material
        name="">
        <color
          rgba="0.79216 0.81961 0.93333 1" />
      </material>
    </visual>
    <collision>
      <origin
        xyz="0 0 0"
        rpy="0 0 0" />
      <geometry>
        <mesh
          filename="package://amr_bot/meshes/sickcam_link.STL" />
      </geometry>
    </collision>
  </link>
  <joint
    name="sickcam_joint"
    type="fixed">
    <origin
      xyz="-0.77559 0.0013357 0.60934"
      rpy="0 0 0" />
    <parent
      link="base_link" />
    <child
      link="sickcam_link" />
    <axis
      xyz="0 0 0" />
  </joint>
</robot>